<?xml version="1.0"?>
<robot name="simple_robot" xmlns:xacro="http://www.ros.org/wiki/xacro">
  <!-- XACRO -->
  <xacro:property name="wheel_radius" value="0.1" />
  <xacro:property name="wheel_length" value="0.05" />
  <xacro:property name="base_size" value="1.0 0.95 0.1" />
  <xacro:property name="base_origin" value="0 0 0.1" />
 
  <!-- links and joint -->
  <!-- Base link (rectangle) -->
  <link name="base_link">
    <visual>
      <geometry>
        <box size="${base_size}"/>
      </geometry>
      <origin xyz="${base_origin}" rpy="0 0 0"/>
      <material name="blue">
        <color rgba="0 0 1 1"/>
      </material>
    </visual>
    <collision>
      <geometry>
        <box size="${base_size}"/>
      </geometry>
    </collision>
    <inertial>
      <mass value="5.0"/>
      <inertia ixx="0.1" ixy="0.0" ixz="0.0"
               iyy="0.1" iyz="0.0"
               izz="0.1"/>
    </inertial>
  </link>

  <!-- Left wheel -->
  <link name="left_wheel">
    <visual>
      <geometry>
        <cylinder radius="${wheel_radius}" length="${wheel_length}" />
      </geometry>
      <origin xyz="0.0 0.25 0.0" rpy="1.5708 0 0"/>
      <material name="black">
        <color rgba="0 0 0 1"/>
      </material>
    </visual>
    <collision>
      <geometry>
        <cylinder radius="${wheel_radius}" length="${wheel_length}" />
      </geometry>
      <origin xyz="0.0 0.25 0.0" rpy="1.5708 0 0"/>
    </collision>
    <inertial>
      <mass value="0.5"/>
      <inertia ixx="0.001" ixy="0.0" ixz="0.0"
               iyy="0.001" iyz="0.0"
               izz="0.001"/>
    </inertial>
    <dynamics damping="0.7" friction="0.2"/>
  </link>

   <!-- Right wheel -->
  <link name="right_wheel">
    <visual>
      <geometry>
        <cylinder radius="${wheel_radius}" length="${wheel_length}" />
      </geometry>
      <origin xyz="0.0 -0.25 0.0" rpy="1.5708 0 0"/>
      <material name="black"/>
    </visual>
    <collision>
      <geometry>
        <cylinder radius="${wheel_radius}" length="${wheel_length}" />
      </geometry>
      <origin xyz="0.0 -0.25 0.0" rpy="1.5708 0 0"/>
    </collision>
    <inertial>
      <mass value="0.5"/>
      <inertia ixx="0.001" ixy="0.0" ixz="0.0"
               iyy="0.001" iyz="0.0"
               izz="0.001"/>
    </inertial>
    <dynamics damping="0.7" friction="0.2"/>
  </link>

  <!-- Left wheel joint -->
  <joint name="left_wheel_joint" type="continuous">
    <parent link="base_link"/>
    <child link="left_wheel"/>
    <origin xyz="0.0 0.25 0.0" rpy="0 0 0"/>
    <axis xyz="0 1 0"/>
    <!-- <limit effort="1.0" velocity="1.0" lower="-1.5708" upper="1.5708"/> -->
  </joint>

  <!-- Right wheel joint -->
  <joint name="right_wheel_joint" type="continuous">
    <parent link="base_link"/>
    <child link="right_wheel"/>
    <origin xyz="0.0 -0.25 0.0" rpy="0 0 0"/>
    <axis xyz="0 1 0"/>
    <!-- <limit effort="1.0" velocity="1.0" lower="-1.5708" upper="1.5708"/> -->
  </joint>

  <!-- Transmission block -->
  <transmission name="left_wheel_trans">
    <type>transmission_interface/SimpleTransmission</type>
    <joint name="left_wheel_joint">
      <hardwareInterface>hardware_interface/VelocityJointInterface</hardwareInterface>
    </joint>
    <actuator name="left_motor">
      <hardwareInterface>hardware_interface/VelocityJointInterface</hardwareInterface>
      <mechanicalReduction>1</mechanicalReduction>
    </actuator>
  </transmission>

  <transmission name="right_wheel_trans">
    <type>transmission_interface/SimpleTransmission</type>
    <joint name="right_wheel_joint">
      <hardwareInterface>hardware_interface/VelocityJointInterface</hardwareInterface>
    </joint>
    <actuator name="right_motor">
      <hardwareInterface>hardware_interface/VelocityJointInterface</hardwareInterface>
      <mechanicalReduction>1</mechanicalReduction>
    </actuator>
  </transmission>

  <!-- ROS2 controls -->
  <ros2_control name="MyRobotHardware" type="system">
  <hardware>
    <plugin>gazebo_ros2_control/GazeboSystem</plugin>
  </hardware>
  <joint name="left_wheel_joint">
    <command_interface name="velocity"/>
    <state_interface name="velocity"/>
  </joint>
  <joint name="right_wheel_joint">
    <command_interface name="velocity"/>
    <state_interface name="velocity"/>
  </joint>
</ros2_control>

<!-- Gazebo block -->
<gazebo>
  <plugin name="gazebo_ros2_control" filename="libgazebo_ros2_control.so"/>
</gazebo>

</robot>